Workbook

Sheet Main

Sheet Target
K2: SEO | L2: Engagement Campaigns | R2: SC + Paid Campaign Leads (Digital) | Y2: Local Campaigns
B3: # | C3: Week | D3: Start | E3: End | F3: Info | G3: MQL / Day | H3: MQL / WK | I3: Investors | J3: Entreprenuers | K3: Website | L3: Whatsapp | M3: SMS | N3: emails | O3: Newsletters | P3: Webinars | Q3: Vodex Phone | R3: YouTube | S3: LinkedIn | T3: Google | U3: Facebook | V3: Instagram | W3: x Twitter | X3: Others | Y3: Events | Z3: Networking | AA3: Others
C4: SPOC | K4: Anil | L4: Vinay | M4: Vinay | N4: Akshaya | O4: Akshaya | P4: Akshaya | Q4: Vinay | R4: Vinay | S4: Akshaya | T4: Akshaya | U4: Anil | V4: Anil | W4: Anil | Y4: Akshaya | Z4: Akshaya
B5: 1 | C5: Week 1 | D5: 29/12/2025 | E5: 46113 | G5: =H5/7 -> 45.714286 | H5: =SUM(K5:AF5) -> 320 | L5: =Calcs!H16 -> 210 | M5: =Calcs!J16 -> 35 | N5: =Calcs!L16 -> 70 | S5: 2 | T5: 3
B6: 2 | C6: Week 2 | D6: 46027 | E6: 46033 | G6: =H6/7 -> 49.285714 | H6: =SUM(K6:AF6) -> 345 | L6: =L5+10 -> 220 | M6: =M5+5 -> 40 | N6: =N5+10 -> 80 | S6: 2 | T6: 3
B7: 3 | C7: Week 3 | D7: =D6+7 -> 46034 | E7: =E6+7 -> 46040 | G7: =H7/7 -> 71.571429 | H7: =SUM(K7:AF7) -> 501 | L7: =L6+10 -> 230 | M7: =M6+5 -> 45 | N7: =N6+10 -> 90 | P7: =Calcs!P16 -> 10 | Q7: =Calcs!R16 -> 120 | S7: 3 | T7: 3
B8: 4 | C8: Week 4 | D8: =D7+7 -> 46041 | E8: =E7+7 -> 46047 | G8: =H8/7 -> 76.142857 | H8: =SUM(K8:AF8) -> 533 | L8: =L7+10 -> 240 | M8: =M7+5 -> 50 | N8: =N7+10 -> 100 | P8: =P7+1 -> 11 | Q8: =Q7+5 -> 125 | S8: 3 | T8: 4
B9: 5 | C9: Week 5 | D9: =D8+7 -> 46048 | E9: =E8+7 -> 46054 | G9: =H9/7 -> 80.714286 | H9: =SUM(K9:AF9) -> 565 | L9: =L8+10 -> 250 | M9: =M8+5 -> 55 | N9: =N8+10 -> 110 | O9: 1 | P9: =P8+1 -> 12 | Q9: =Q8+5 -> 130 | S9: 3 | T9: 4
B10: 6 | C10: Week 6 | D10: =D9+7 -> 46055 | E10: =E9+7 -> 46061 | G10: =H10/7 -> 85.285714 | H10: =SUM(K10:AF10) -> 597 | L10: =L9+10 -> 260 | M10: =M9+5 -> 60 | N10: =N9+10 -> 120 | O10: 1 | P10: =P9+1 -> 13 | Q10: =Q9+5 -> 135 | S10: 4 | T10: 4
B11: 7 | C11: Week 7 | D11: =D10+7 -> 46062 | E11: =E10+7 -> 46068 | G11: =H11/7 -> 89.857143 | H11: =SUM(K11:AF11) -> 629 | L11: =L10+10 -> 270 | M11: =M10+5 -> 65 | N11: =N10+10 -> 130 | O11: 1 | P11: =P10+1 -> 14 | Q11: =Q10+5 -> 140 | S11: 4 | T11: 5
B12: 8 | C12: Week 8 | D12: =D11+7 -> 46069 | E12: =E11+7 -> 46075 | G12: =H12/7 -> 94.285714 | H12: =SUM(K12:AF12) -> 660 | L12: =L11+10 -> 280 | M12: =M11+5 -> 70 | N12: =N11+10 -> 140 | O12: 1 | P12: =P11+1 -> 15 | Q12: =Q11+5 -> 145 | S12: 4 | T12: 5
B13: 9 | C13: Week 9 | D13: =D12+7 -> 46076 | E13: =E12+7 -> 46082 | G13: =H13/7 -> 98.714286 | H13: =SUM(K13:AF13) -> 691 | L13: =L12+10 -> 290 | M13: =M12+5 -> 75 | N13: =N12+10 -> 150 | O13: 1 | P13: =P12+1 -> 16 | Q13: =Q12+5 -> 150 | S13: 4 | T13: 5
B14: 10 | C14: Week 10 | D14: =D13+7 -> 46083 | E14: =E13+7 -> 46089 | G14: =H14/7 -> 103.14286 | H14: =SUM(K14:AF14) -> 722 | L14: =L13+10 -> 300 | M14: =M13+5 -> 80 | N14: =N13+10 -> 160 | O14: 1 | P14: =P13+1 -> 17 | Q14: =Q13+5 -> 155 | S14: 4 | T14: 5
B15: 11 | C15: Week 11 | D15: =D14+7 -> 46090 | E15: =E14+7 -> 46096 | G15: =H15/7 -> 107.57143 | H15: =SUM(K15:AF15) -> 753 | L15: =L14+10 -> 310 | M15: =M14+5 -> 85 | N15: =N14+10 -> 170 | O15: 1 | P15: =P14+1 -> 18 | Q15: =Q14+5 -> 160 | S15: 4 | T15: 5
B16: 12 | C16: Week 12 | D16: =D15+7 -> 46097 | E16: =E15+7 -> 46103 | G16: =H16/7 -> 111 | H16: =SUM(K16:AF16) -> 777 | L16: =L15+10 -> 320 | M16: =M15+5 -> 90 | N16: =N15+10 -> 180 | O16: 3 | P16: =P15+1 -> 19 | Q16: =Q15+5 -> 165
B17: 13 | C17: Week 13 | D17: =D16+7 -> 46104 | E17: =E16+7 -> 46110 | G17: =H17/7 -> 115.42857 | H17: =SUM(K17:AF17) -> 808 | L17: =L16+10 -> 330 | M17: =M16+5 -> 95 | N17: =N16+10 -> 190 | O17: 3 | P17: =P16+1 -> 20 | Q17: =Q16+5 -> 170
B18: 14 | C18: Week 14 | D18: =D17+7 -> 46111 | E18: =E17+7 -> 46117 | G18: =H18/7 -> 119.85714 | H18: =SUM(K18:AF18) -> 839 | L18: =L17+10 -> 340 | M18: =M17+5 -> 100 | N18: =N17+10 -> 200 | O18: 3 | P18: =P17+1 -> 21 | Q18: =Q17+5 -> 175
B19: 15 | C19: Week 15 | D19: =D18+7 -> 46118 | E19: =E18+7 -> 46124 | G19: =H19/7 -> 124.28571 | H19: =SUM(K19:AF19) -> 870 | L19: =L18+10 -> 350 | M19: =M18+5 -> 105 | N19: =N18+10 -> 210 | O19: 3 | P19: =P18+1 -> 22 | Q19: =Q18+5 -> 180
B20: 16 | C20: Week 16 | D20: =D19+7 -> 46125 | E20: =E19+7 -> 46131 | G20: =H20/7 -> 128.85714 | H20: =SUM(K20:AF20) -> 902 | L20: =L19+10 -> 360 | M20: =M19+5 -> 110 | N20: =N19+10 -> 220 | O20: 4 | P20: =P19+1 -> 23 | Q20: =Q19+5 -> 185
B21: 17 | C21: Week 17 | D21: =D20+7 -> 46132 | E21: =E20+7 -> 46138 | G21: =H21/7 -> 133.28571 | H21: =SUM(K21:AF21) -> 933 | L21: =L20+10 -> 370 | M21: =M20+5 -> 115 | N21: =N20+10 -> 230 | O21: 4 | P21: =P20+1 -> 24 | Q21: =Q20+5 -> 190
B22: 18 | C22: Week 18 | D22: =D21+7 -> 46139 | E22: =E21+7 -> 46145 | G22: =H22/7 -> 137.71429 | H22: =SUM(K22:AF22) -> 964 | L22: =L21+10 -> 380 | M22: =M21+5 -> 120 | N22: =N21+10 -> 240 | O22: 4 | P22: =P21+1 -> 25 | Q22: =Q21+5 -> 195
B23: 19 | C23: Week 19 | D23: =D22+7 -> 46146 | E23: =E22+7 -> 46152 | G23: =H23/7 -> 142.14286 | H23: =SUM(K23:AF23) -> 995 | L23: =L22+10 -> 390 | M23: =M22+5 -> 125 | N23: =N22+10 -> 250 | O23: 4 | P23: =P22+1 -> 26 | Q23: =Q22+5 -> 200
B24: 20 | C24: Week 20 | D24: =D23+7 -> 46153 | E24: =E23+7 -> 46159 | G24: =H24/7 -> 146.71429 | H24: =SUM(K24:AF24) -> 1027 | L24: =L23+10 -> 400 | M24: =M23+5 -> 130 | N24: =N23+10 -> 260 | O24: 5 | P24: =P23+1 -> 27 | Q24: =Q23+5 -> 205
B25: 21 | C25: Week 21 | D25: =D24+7 -> 46160 | E25: =E24+7 -> 46166 | G25: =H25/7 -> 151.14286 | H25: =SUM(K25:AF25) -> 1058 | L25: =L24+10 -> 410 | M25: =M24+5 -> 135 | N25: =N24+10 -> 270 | O25: 5 | P25: =P24+1 -> 28 | Q25: =Q24+5 -> 210
B26: 22 | C26: Week 22 | D26: =D25+7 -> 46167 | E26: =E25+7 -> 46173 | G26: =H26/7 -> 155.57143 | H26: =SUM(K26:AF26) -> 1089 | L26: =L25+10 -> 420 | M26: =M25+5 -> 140 | N26: =N25+10 -> 280 | O26: 5 | P26: =P25+1 -> 29 | Q26: =Q25+5 -> 215
B27: 23 | C27: Week 23 | D27: =D26+7 -> 46174 | E27: =E26+7 -> 46180 | G27: =H27/7 -> 160 | H27: =SUM(K27:AF27) -> 1120 | L27: =L26+10 -> 430 | M27: =M26+5 -> 145 | N27: =N26+10 -> 290 | O27: 5 | P27: =P26+1 -> 30 | Q27: =Q26+5 -> 220
G28: =H28/7 -> 164.57143 | H28: =SUM(K28:AF28) -> 1152 | L28: =L27+10 -> 440 | M28: =M27+5 -> 150 | N28: =N27+10 -> 300 | O28: 6 | P28: =P27+1 -> 31 | Q28: =Q27+5 -> 225
L29: =L28+10 -> 450 | M29: =M28+5 -> 155 | N29: =N28+10 -> 310 | O29: 6 | P29: =P28+1 -> 32 | Q29: =Q28+5 -> 230

Sheet Report
E1: Visitors | H1: Leads
B2: Week | C2: Start Date | D2: End Date | E2: # Visitors | F2: SEO | G2: PPC Campaign | H2: MQL | I2: SEO | J2: PPC Campaign
B3: Week 1 | C3: 29/12/2025 | D3: 46113
B4: Week 2 | C4: 46027 | D4: 46033
B5: Week 3 | C5: =C4+7 -> 46034 | D5: =D4+7 -> 46040
B6: Week 4 | C6: =C5+7 -> 46041 | D6: =D5+7 -> 46047
B7: Week 5 | C7: =C6+7 -> 46048 | D7: =D6+7 -> 46054
B8: Week 6 | C8: =C7+7 -> 46055 | D8: =D7+7 -> 46061
B9: Week 7 | C9: =C8+7 -> 46062 | D9: =D8+7 -> 46068
B10: Week 8 | C10: =C9+7 -> 46069 | D10: =D9+7 -> 46075
B11: Week 9 | C11: =C10+7 -> 46076 | D11: =D10+7 -> 46082
B12: Week 10 | C12: =C11+7 -> 46083 | D12: =D11+7 -> 46089
B13: Week 11 | C13: =C12+7 -> 46090 | D13: =D12+7 -> 46096
B14: Week 12 | C14: =C13+7 -> 46097 | D14: =D13+7 -> 46103
B15: Week 13 | C15: =C14+7 -> 46104 | D15: =D14+7 -> 46110
B16: Week 14 | C16: =C15+7 -> 46111 | D16: =D15+7 -> 46117
... B25: Week 23 | C25: =C24+7 -> 46174 | D25: =D24+7 -> 46180

Sheet Calcs
B2: 7 Days Campaign | I2: 1st TPs - New Contacts | R2: # minutes
B3: Weekend rota | D3: Hrs | F3: Total | H3: WhatsApp | I3: SMS | J3: SMS | K3: emails | L3: emails | N3: News letter | P3: Webinars | R3: Vodex AI
C4: Day | D4: 8 | H4: 1000 | J4: 500 | L4: 1000 | N4: 300 | R4: 200
C5: Per Week | E5: 7 | H5: =H4*E5 -> 7000 | J5: =J4*$E$5 -> 3500 | L5: =L4*E5 -> 7000 | P5: 100 | R5: =R4*E5 -> 1400
C6: Per Month | E6: 4 | H6: =H5*E6 -> 28000 | J6: =J5*E6 -> 14000 | L6: =L5*E6 -> 28000 | P6: =P5*E6 -> 400 | R6: =R5*E6 -> 5600
C8: Data is relevant
B10: Success Rate
C11: Open Rate | D11: 85 - 98 % | E11: 0.9 | H11: =$H$6*E11 -> 25200
C12: CTA Button Click | D12: 5- 12% | E12: 0.08 | H12: =$H$6*E12 -> 2240
B13: 1 | C13: Leads (Best Case) | D13: 6 - 14% | E13: 0.1 | H13: =$H$6*E13 -> 2800 | I13: 0.04 | O13: 0.25 | Q13: 0.3
B14: 2 | C14: Leads (Practical) | E14: 0.06 | H14: =H6*E14 -> 1680 | I14: 0.02
B15: 3 | C15: Leads (Worst Case) | E15: 0.03 | H15: =H6*E15 -> 840 | I15: 0.01 | J15: =J6*I15 -> 140 | K15: 0.01 | L15: =L6*K15 -> 280 | M15: 0.01 | N15: =N4*M15 -> 3 | O15: 0.1 | P15: =P6*O15 -> 40 | Q15: 0.15 | R15: =R6*Q15 -> 840
C16: Per Week | H16: =H15/4 -> 210 | J16: =J15/4 -> 35 | L16: =L15/4 -> 70 | N16: =N15/4 -> 0.75 | P16: =P15/4 -> 10 | R16: =R15/7 -> 120
C17: per Day | H17: =H16/7 -> 30 | I17: =I16/7 -> 0 | J17: =J16/7 -> 5 | K17: =K16/7 -> 0 | L17: =L16/7 -> 10 | N17: =N16/7 -> 0.10714286 | R17: =R16/7 -> 17.142857
C23: Rate
C24: How many Tools

Sheet SEO
A2: A | B2: ON-page optimisation | C2: Start | D2: Status | E2: Ranking | F2: Notes
A3: 1 | B3: Website Analysis | C3: 45972 | D3: Done
A4: 2 | B4: Keyword Research | C4: 25/11/2025 | D4: Done
A5: 3 | B5: Competition Analysis | C5: 24/11/2025 | D5: Done
A6: 4 | B6: Backlink Analysis | C6: 23/12/2025 | D6: In progress
A7: 5 | B7: Initial Ranking Report | C7: NO | D7: NO
A8: 6 | B8: Website Structure Optimization | C8: NO | D8: NO
A9: 7 | B9: Meta tag Creation & Optimization | C9: 27/11/2025 | D9: Done
A10: 8 | B10: Headings Optimization (h1 & h2) | C10: 45912 | D10: Done
A11: 9 | B11: Urls Optimization | C11: NO | D11: NO
A12: 10 | B12: Images Optimization | C12: 45912 | D12: Done
A13: 11 | B13: XML Sitemap Creation | C13: 46003 | D13: Done
A14: 12 | B14: Robots.txt Optimization
A15: 13
A16: 14
A17: 15
A18: 16 | B18: OFF-page optimisation | C18: 22/12/2025 | D18: In progress
A19: 17 | B19: Directory submissions.
A20: 18 | B20: Social Bookmaking Submissions.
A21: 19 | B21: Article Submissions
A22: 20 | B22: Press Release Submissions
A23: 21 | B23: Blog Submissions.
A24: 22 | B24: One Way back links with mix PR
A25: 23
A26: 24
A27: 25
A28: 26
A29: 27
A30: 28

Sheet approach
P3: Approach | Q3: Unsuccessful | R3: Sucessful
C5: Concerns around hitting Targets / Success Rate | P5: 1st Touch point | Q5: Whatsapp | R5: STOP
C7: Data | P7: 2nd Touch point | Q7: SMS | R7: STOP
E8: Relevance of the Data | I8: Ensure the data is relevant
I9: Properly classified | P9: 3rd Touch point | Q9: email | R9: STOP
I10: Review every campaign to ensure the data quality
P11: 4th Touch Point | Q11: Repeat -Comms
C13: Tools and Limits | P13: 5th Touch Point | Q13: Vodex
E15: Limitations on # messages | I15: Use Multimple Tools | P15: 6th Touch Point - Final | Q15: Telesales
I16: Don't depend on one tool eg. GupShup,
I17: Try other althernative 3 to 5 Tools
C19: Content
E20: User for CTA - clicks | I20: Offers, Knowledge, use ful info
I21: Create Sense of urgency
I22: Bring reference
C25: Specific - touch points
E27: Connecting Dots | I27: Variables saved in the system
I28: Dates, Number of touches
I29: Clicks
I30: Calendar invitations
I31: Tickets for events
I32: Webinar links
I33: ✅ Education-led emails (not selling)
I34: ✅ Market insights / deal notes
I35: ✅ Founder POV / credibility stories
I36: ✅ Event invitations (webinars, dinners)
I37: ✅ Case studies (compliance-safe)
I38: ✅ Soft CTA → WhatsApp / Call

Sheet Tools
A1: # | B1: Tool | C1: Particulars | D1: Classification | E1: Campaigns | F1: SPOC | G1: Backup | H1: URL | I1: User Name | J1: PW | K1: Account / Ref | L1: Cost - Set up | M1: Cost - Per month | N1: Cost - Variable | O1: Notes
A2: 1 | B2: GupShup | D2: Comms | E2: WhatsApp, SMS, Insta, email, SC | F2: Vinay
A3: 2 | B3: Brevo | E3: WhatsApp, emails | F3: Team
A4: 3 | B4: Zoho | E4: SMS, Emails, | F4: Team
A5: 4 | B5: Hubspot | F5: Team
A6: 5 | B6: SEO Tool Add | C6: SEM Rush, AI tools | F6: Team
A7: 6 | B7: Google Analytics | F7: Team
A8: 7 | B8: Google Search Console | F8: Team
A9: 8 | B9: Vodex | F9: Vinay
A10: 9 | B10: Holo | C10: Content and Design AI | F10: Gayatri | H10: https://tryholo.ai/
A11: 10 | B11: Canva | D11: Design | F11: Anil Raj
A12: 11 | B12: Adobe Premium | D12: Design | F12: Team 1
A13: 12 | B13: ChatGPT Enterprise/ Paid | D13: Content, Design + | F13: Team
A14: 13
A15: 14
A16: 15
A17: 16
A18: 17
A19: 18
A20: 19
A21: 20
A22: 21
A23: 22
A24: 23
A25: 24
A26: 25

Sheet Action Items
A1: # | B1: Task | C1: Particulars | D1: Owner | E1: Start Date | F1: Due Date | G1: Status | H1: Notes
A2: 1 | B2: Keyword analysis | C2: Top 20 Keywords, competiton and full analysis | D2: Anil
A3: 2 | B3: WEBSITE – Mktg page builders
A4: 3 | B4: Landing pages
A5: 4 | B5: Squeeze pages
A6: 5 | B6: Sales pages
A7: 6 | B7: Thank you pages
A8: 7 | B8: Product Launch pages
A9: 8 | B9: Checkout pages
A10: 9 | B10: Video Sales letter pages
A11: 10 | B11: Membership portal builders
A12: 11 | B12: Shopping carts
A13: 12 | B13: Online form builders
A14: 13 | B14: Split testing and link tracking
... A16: 15 | B16: AI Marketing Stack
A17: 16 | B17: Marketing Analytics Stack | C17: SEO Adda 40 + tools
A18: 17 | B18: Graphics & Designs AI stack
A19: 18 | B19: Vodex platform live
A20: 19 | B20: Whatsapp live
A21: 20
A22: 21
A23: 22
A24: 23
A25: 24
A26: 25
A27: 26

Sheet SEO Adda Tools

Sheet SEO On-page
A1: Pages | B1: Keywords | C1: Title Tag | D1: Meta Description
A2: https://ritzgroup.co/ | B2: Best Investment Company in India , Ritz Group | C2: Best Investment Company in India | Ritz Group | D2: Ritz Group – Best Investment Company in India offering Venture Capital, Fund Management, Investors Club, and Micro & Macro Investment services.
A3: https://ritzgroup.co/venture-capital | B3: Top Venture Capital Firms in India 2025 , Ritz Group | C3: Top Venture Capital Firms in India 2025 | Ritz Group | D3: Discover why Ritz Group ranks among the top venture capital firms in India 2025, empowering startups with expert fund management, private equity, and investment growth.
A4: https://ritzgroup.co/fund-management | B4: Fund Management services in India , Ritz Group | C4: Fund Management services in India - Ritz Group | D4: Ritz Group stands among Fund Management services in India, offering expert fund management, portfolio growth, and venture capital solutions.
A5: https://ritzgroup.co/investors-club | B5: Business Investors in India , Investors Clubs | C5: Business Investors in India | Investors Clubs | D5: Discover leading business investors in India and exclusive investors clubs by Ritz Group, offering startup funding, venture capital, and investment growth.
A6: https://ritzgroup.co/micro-and-macro-investment | B6: Micro & Macro Investments in India , RitzGroup | C6: Micro & Macro Investments in India | RitzGroup | D6: Explore smart micro and macro investment opportunities in India with RitzGroup. Start small, grow steadily, and secure your financial future expert guidance.

Sheet Trending Keywords
A1: No | B1: Keyword | C1: Search Volume | D1: SEO Difficulty
A2: 1 | B2: best investment companies in india | C2: 480 | D2: 34
A3: 2 | B3: top 20 investment companies in india | C3: 590 | D3: 33
A4: 3 | B4: best company in india for investment | C4: 480 | D4: 12
A5: 4 | B5: best alternative investment funds in india | C5: 320 | D5: 22
A6: 5 | B6: top investment banking companies in india | C6: 320 | D6: 29
A7: 6 | B7: top 10 housing finance companies in india 2024 | C7: 110 | D7: 7
A8: 7 | B8: best investment companies in the world | C8: 90 | D8: 12
A9: 8 | B9: best investment plan in india for 5 years | C9: 70 | D9: 29
A10: 9 | B10: top 100 finance companies in india pdf | C10: 70 | D10: 6
A11: 10 | B11: best micro finance company in india | C11: 70 | D11: 10
A12: 11 | B12: best sip investment company in india | C12: 50 | D12: 26
A13: 12 | B13: best investment plan for 3 years in india | C13: 50 | D13: 26
... A47: 46 | B47: top investment holding companies in india | C47: 10 | D47: 5
B49: venture capital
A50: No | B50: Keyword | C50: Search Volume | D50: SEO Difficulty
A51: 1 | B51: top venture capital firms in india | C51: 1000 | D51: 25
A52: 2 | B52: top venture capitalists in india | C52: 1300 | D52: 30
A53: 3 | B53: top investment firms in india | C53: 140 | D53: 9
A54: 4 | B54: top venture capital firms in bangalore | C54: 50 | D54: 5
A55: 5 | B55: top seed funding companies in india | C55: 40 | D55: 7
A56: 6 | B56: top venture capital firms in mumbai | C56: 20 | D56: 5
A57: 7 | B57: highest paying venture capital firms in india | C57: 0 | D57: 4
A58: 8 | B58: top venture capital firms in delhi | C58: 0 | D58: 4
A59: 9 | B59: top 5 venture capitalists in india | C59: 0 | D59: 4
A60: 10 | B60: top investment companies in india for long term | C60: 0 | D60: 4
A61: 11 | B61: Top Venture Capital Firms & Investors in India in 2025 | C61: 0 | D61: 4
B63: Fund Management
A64: No | B64: Keyword | C64: Search Volume | D64: SEO Difficulty
A65: 1 | B65: fund management india | C65: 320 | D65: 20
A66: 2 | B66: mutual funds in india top 10 | C66: 5400 | D66: 27
A67: 3 | B67: investment management companies india | C67: 1600 | D67: 9
A68: 4 | B68: mutual funds in india comparison | C68: 1600 | D68: 9
A69: 5 | B69: etf funds in india list | C69: 880 | D69: 51
A70: 6 | B70: fund management companies | C70: 880 | D70: 51
A71: 7 | B71: fund manager salary in india | C71: 590 | D71: 33
A72: 8 | B72: invesco asset management india private limited | C72: 590 | D72: 7
A73: 9 | B73: innovations investment management india private limited | C73: 590 | D73: 18
A74: 10 | B74: mutual funds in india with best returns | C74: 590 | D74: 17
A75: 11 | B75: asset management company india | C75: 480 | D75: 9
...

Sheet Ritz keywords
A1: Key words
A2: Best Investment Company in India
A3: Top Venture Capital Firms in India 2025
A4: Fund Management services in India
A5: Business Investors in India | Investors Clubs
A6: Micro & Macro Investments in India
A7: Ritz Group – GreenTech, FinTech & HealthTech Investments

Sheet SE0 Off - page backlinks
A1: Date | B1: Referring URl | C1: DA | D1: PA | E1: Type of Submission | F1: Submitted URl | G1: Status
A2: 23/12/2025 | B2: Profile submission
B3: https://www.ranker.com/ | C3: 95 | D3: 85 | E3: Profile Creation | F3: https://www.ranker.com/writer/ritz-group
B4: https://devfolio.co/ | C4: 76 | D4: 64 | E4: Profile Creation | F4: https://devfolio.co/@Ritzgroup
B5: https://www.atlasobscura.com/ | C5: 83 | D5: 68 | E5: Profile Creation | F5: https://www.atlasobscura.com/users/9f4f3c46-ee34-4a9b-bd72-61cffd6b8ab8
B6: https://www.answers.com/ | C6: 15 | D6: 24 | E6: Profile Creation | F6: https://www.answers.com/u/ritzgroup
B7: https://www.indiegogo.com/ | C7: 90 | D7: 70 | E7: Profile Creation | F7: https://www.indiegogo.com/en/profile/ritz12345#/overview
B8: https://bookmarkrange.com/ | C8: 54 | D8: 45 | E8: Profile Creation | F8: https://bookmarkrange.com/user/ritzgroup1122
B9: https://www.pinterest.com/ | C9: 35 | D9: 56 | E9: Profile Creation | F9: https://www.pinterest.com/ritzgroupco123/
B10: SBMS Submission
B11: https://bookmarkrange.com/ | C11: 11 | D11: 42 | E11: SBMS | F11: https://bookmarkrange.com/story22617237/how-to-choose-the-right-investment-company-for-long-term-wealth-growth
B12: https://bookmarkbirth.com/ | C12: 15 | D12: 40 | E12: SBMS | F12: https://bookmarkbirth.com/story21340511/how-to-choose-the-right-investment-company-for-long-term-wealth-growth
B13: https://www.bookmarkfeeds.com | C13: 55 | D13: 64 | E13: SBMS | F13: https://www.bookmarkfeeds.com/preview-article/
B14: https://www.socialbookmarknow.info/ | C14: 18 | D14: 41 | E14: SBMS | F14: https://www.socialbookmarknow.info/preview-article/
B15: https://www.publicbuysell.com/ | C15: 42 | D15: 55 | E15: SBMS | F15: https://www.publicbuysell.com/preview-post/
B16: Directory Submission
B17: https://caida.eu/ | C17: 17 | D17: 45 | E17: Directories | F17: https://caida.eu/submit.php
B18: https://www.fire-directory.com/ | C18: 32 | D18: 51 | E18: Directories | F18: https://www.fire-directory.com/submit.php
B19: https://www.craigslist.org/ | C19: 88 | D19: 76 | E19: Directories | F19: https://hyderabad.craigslist.org/fns/d/how-to-choose-the-right-investment/7904178770.html
B20: https://linkdirectorylistings.org/ | C20: 73 | D20: 42 | E20: Directories | F20: https://linkdirectorylistings.org/submit-site/
B21: https://www.dizila.com/ | C21: 17 | D21: 45 | E21: Directories | F21: https://www.dizila.com/submit?c=27&LINK_TYPE=1
B22: Classifieds
B23: https://www.locanto.org | C23: 15 | D23: 23 | E23: Clasifieds | F23: https://www.locanto.org/nanakramguda/ID_8111869115/How-to-Choose-the-Right-Investment-Company-for-Long-Term-Wealth.html
B24: https://www.freeclassifiedssites.com/ | C24: 29 | D24: 50 | E24: Clasifieds | F24: https://www.freeclassifiedssites.com/index.php?view=post&cityid=609&lang=en&catid=12&subcatid=82&shortcutregion=&
B25: https://hyderabad.indads.in/ | C25: 20 | D25: 34 | E25: Clasifieds | F25: https://hyderabad.indads.in/item/1370065/
B26: https://hyderabad.classifiedsfactor.com/ | C26: 26 | D26: 29 | E26: Clasifieds | F26: https://items.classifiedsfactor.com/post-a-classified-ad-type.php
B27: https://www.advertiseera.com | C27: 22 | D27: 44 | E27: Clasifieds | F27: https://www.advertiseera.com/post-an-ad-step-6.php
A29: 24/12/2025 | B29: Profile submission
B30: https://justpaste.it/ | C30: 76 | D30: 64 | E30: Profile Creation | F30: https://justpaste.it/u/Ritzgroup1122
B31: https://medium.com/ | C31: 83 | D31: 68 | E31: Profile Creation | F31: https://medium.com/@ritzgroupco123
B32: https://dev.to/ | C32: 83 | D32: 68 | E32: Profile Creation | F32: https://dev.to/ritz_group_00b92b8a0f04df
B33: https://www.spreaker.com | C33: 90 | D33: 70 | E33: Profile Creation | F33: https://www.spreaker.com/user/ritz-group--18836066
B34: www.gitlab.com | C34: 92 | D34: 66 | E34: Profile Creation | F34: https://gitlab.com/ritzgroupco123
B35: https://altbookmark.com/ | C35: 15 | D35: 37 | E35: Profile Creation | F35: https://altbookmark.com/user/ritzgroup1122
B36: https://hindibookmark.com/ | C36: 89 | D36: 76 | E36: Profile Creation | F36: https://hindibookmark.com/user/ritzgroup1122
B37: https://claz.org/ | C37: 52 | D37: 55 | E37: Profile Creation | F37: https://claz.org/user/account
B38: https://www.quora.com/ | C38: 95 | D38: 86 | E38: Profile Creation | F38: https://www.quora.com/profile/Ritz-Group
B39: SBMS Submission
B40: https://www.submitcorp.com/ | C40: 28 | D40: 50 | E40: SBMS | F40: https://www.submitcorp.com/preview-business/ | G40: Pending
B41: https://www.peoplebookmarks.com/ | C41: 12 | D41: 41 | E41: SBMS | F41: https://www.peoplebookmarks.com/preview-bookmark/ | G41: Pending
...

Sheet web 2.0 backlinks
A1: Date | B1: URL | C1: Submission URL
A2: 23/12/2025 | B2: https://ko-fi.com | C2: https://ko-fi.com/i/IP5P51QBOMZ | D2: Gmail | E2: Password
B3: https://www.reddit.com/ | C3: https://www.reddit.com/r/investing_discussion/comments/1pn6oq7/best_investment_company_in_india_a_complete_guide/ | D3: ritzgroupco123@gmail.com | E3: Ritzgroup@1122
B4: https://justpaste.it | C4: https://justpaste.it/kh718
B5: https://www.blogger.com/ | C5: https://ritzgroupco1.blogspot.com/2025/12/best-investment-company-in-india.html
B6: https://medium.com | C6: https://medium.com/@ritzgroupco123/best-investment-company-in-india-a-complete-guide-to-smart-wealth-building-d2c4d8e33dc6?postPublishedType=initial
B7: https://www.tumblr.com | C7: https://www.tumblr.com/ritz1122/803002568796160000/best-investment-company-in-india-a-complete-guide?source=share
B8: https://pastes.io | C8: https://pastes.io/best-investment-company-in-india-a-complete-guide-to-smart-wealth-building
B9: https://www.diigo.com/ | C9: https://www.diigo.com/item/note/bpr5u/wsyx?k=9dc5059e0cf4df1b40f56717c0462ac2
B10: LiveJournal.com | C10: https://ext-6891250.livejournal.com/260.html
B11: https://blogs.hyvor.com/ | C11: https://ritz.hyvorblogs.io/best-investment-company-in-india-a-complete-guide-to-smart-wealth-building
B12: https://potswap.club | C12: https://potswap.club/posts/198705
B13: https://blogger-mania.mn.co/ | C13: https://blogger-mania.mn.co/posts/95068636?utm_source=manual
A15: 24/12/2025 | B15: https://justpaste.it | C15: https://justpaste.it/hj9y8
B16: https://www.blogger.com/ | C16: https://ritzgroupco1.blogspot.com/2025/12/how-to-choose-right-investment-company.html
B17: https://medium.com | C17: https://medium.com/@ritzgroupco123/how-to-choose-the-right-investment-company-for-long-term-wealth-growth-e60502903b4b?postPublishedType=initial
B18: https://www.tumblr.com | C18: https://www.tumblr.com/ritz1122/803789950252466176/how-to-choose-the-right-investment-company-for?source=share
B19: https://www.reddit.com/ | C19: https://www.reddit.com/r/investing/comments/1pufoft/how_to_choose_the_right_investment_company_for/
B20: LiveJournal.com | C20: https://ext-6891250.livejournal.com/1313.html
B21: https://www.diigo.com/ | C21: https://www.diigo.com/annotated/7ba0d26668e0f6d4cce3092596d47ba4
A23: 29/12/2025 | B23: https://justpaste.it | C23: https://justpaste.it/jrncm
B24: https://www.blogger.com/ | C24: https://ritzgroupco1.blogspot.com/2025/12/top-fund-management-services-in-india.html
B25: https://medium.com | C25: https://medium.com/@ritzgroupco123/top-fund-management-services-in-india-features-benefits-how-to-choose-the-right-one-5806fbd5c0df?postPublishedType=initial
B26: https://www.tumblr.com | C26: https://www.tumblr.com/ritz1122/804257130316201984/top-fund-management-services-in-india-features?source=share
B27: https://www.reddit.com/ | C27: https://www.reddit.com/r/investing/comments/1pyiw6b/top_fund_management_services_in_india_features/
B28: LiveJournal.com | C28: https://www.livejournal.com/post/?draft=https://ext-6891250.livejournal.com/d6.html
B29: https://www.diigo.com/ | C29: https://www.diigo.com/annotated/906f039359f87bd8bc12c1cc8338cb24
B30: https://ko-fi.com | C30: https://ko-fi.com/i/IP5P51QBOMZ
A32: 30/12/2025 | B32: https://justpaste.it | C32: https://justpaste.it/m7tf4
B33: https://www.blogger.com/ | C33: https://ritzgroupco1.blogspot.com/2025/12/ritz-group-greentech-fintech-healthtech.html
B34: https://medium.com | C34: https://medium.com/@ritzgroupco123/ritz-group-greentech-fintech-healthtech-investments-building-the-future-of-smart-capital-161ff9c181c7?postPublishedType=initial
B35: https://www.tumblr.com | C35: https://www.tumblr.com/ritz1122/804353592413782016/ritz-group-greentech-fintech-healthtech?source=share
B36: https://www.reddit.com/ | C36: https://www.reddit.com/r/investing_discussion/comments/1pzf2z8/ritz_group_greentech_fintech_healthtech/
B37: LiveJournal.com | C37: https://www.livejournal.com/post/?draft=https://ext-6891250.livejournal.com/d7.html
B38: https://www.diigo.com/ | C38: https://www.diigo.com/user/ritzgroup/b/813089518
A40: 31/12/2025 | B40: https://justpaste.it | C40: https://justpaste.it/e36fi
B41: https://www.blogger.com/ | C41: https://ritzgroupco1.blogspot.com/2025/12/micro-macro-investments-in-india.html
B42: https://medium.com | C42: https://medium.com/@ritzgroupco123/micro-macro-investments-in-india-a-complete-guide-for-smart-wealth-building-in-2025-972dc962a2bb?postPublishedType=initial
B43: https://www.tumblr.com | C43: https://www.tumblr.com/ritz1122/804445430537764864/micro-macro-investments-in-india-a-complete?source=share
B44: https://www.reddit.com/ | C44: https://www.reddit.com/r/Investments/comments/1q0aqkg/best_investment_company_in_india/
...

Sheet Profile Creations
A1: Referring URl | B1: DA | C1: PA | D1: Type of Submission | E1: Submitted URl | F1: Status
A2: https://www.ranker.com/ | B2: 95 | C2: 85 | D2: Profile Creation | E2: https://www.ranker.com/writer/ritz-group | G2: Gmail | H2: Password
A3: https://devfolio.co/ | B3: 76 | C3: 64 | D3: Profile Creation | E3: https://devfolio.co/@Ritzgroup | G3: ritzgroupco123@gmail.com | H3: Ritzgroup@1122
A4: https://www.atlasobscura.com/ | B4: 83 | C4: 68 | D4: Profile Creation | E4: https://www.atlasobscura.com/users/9f4f3c46-ee34-4a9b-bd72-61cffd6b8ab8
A5: https://www.answers.com/ | B5: 15 | C5: 24 | D5: Profile Creation | E5: https://www.answers.com/u/ritzgroup
A6: https://www.indiegogo.com/ | B6: 90 | C6: 70 | D6: Profile Creation | E6: https://www.indiegogo.com/en/profile/ritz12345#/overview
A7: https://bookmarkrange.com/ | B7: 54 | C7: 45 | D7: Profile Creation | E7: https://bookmarkrange.com/user/ritzgroup1122
A8: https://www.pinterest.com/ | B8: 35 | C8: 56 | D8: Profile Creation | E8: https://www.pinterest.com/ritzgroupco123/
A9: 24/12/2025
A10: https://justpaste.it/ | B10: 76 | C10: 64 | D10: Profile Creation | E10: https://justpaste.it/u/Ritzgroup1122
A11: https://medium.com/ | B11: 83 | C11: 68 | D11: Profile Creation | E11: https://medium.com/@ritzgroupco123
A12: https://dev.to/ | B12: 83 | C12: 68 | D12: Profile Creation | E12: https://dev.to/ritz_group_00b92b8a0f04df
A13: https://www.spreaker.com | B13: 90 | C13: 70 | D13: Profile Creation | E13: https://www.spreaker.com/user/ritz-group--18836066
A14: www.gitlab.com | B14: 92 | C14: 66 | D14: Profile Creation | E14: https://gitlab.com/ritzgroupco123
A15: https://altbookmark.com/ | B15: 15 | C15: 37 | D15: Profile Creation | E15: https://altbookmark.com/user/ritzgroup1122
A16: https://hindibookmark.com/ | B16: 89 | C16: 76 | D16: Profile Creation | E16: https://hindibookmark.com/user/ritzgroup1122
A17: https://claz.org/ | B17: 52 | C17: 55 | D17: Profile Creation | E17: https://claz.org/user/account
A18: https://www.quora.com/ | B18: 95 | C18: 86 | D18: Profile Creation | E18: https://www.quora.com/profile/Ritz-Group
A19: 29/12/2025
A20: www.pixlr.com | B20: 87 | C20: 66 | D20: Profile Creation | E20: https://pixlr.com/myaccount/
A21: https://manage.wix.com/ | B21: 44 | C21: 53 | D21: Profile Creation | E21: https://manage.wix.com/dashboard/c16d17bc-504a-4b82-9ad8-c0f581521d29/setup
A22: https://thejavasea.me/ | B22: 28 | C22: 40 | D22: Profile Creation | E22: https://thejavasea.me/members/ritzgroup.370953/
A23: https://participez.nouvelle-aquitaine.fr | B23: 61 | C23: 44 | D23: Profile Creation | E23: https://participez.nouvelle-aquitaine.fr/profiles/ritzgroup/timeline?locale=en
A24: https://www.tripit.com/ | B24: 78 | C24: 64 | D24: Profile Creation | E24: https://www.tripit.com/app/account/profile
A25: github.com | B25: 96 | C25: 93 | D25: Profile Creation | E25: https://github.com/ritzgroupco123-lgtm
A26: https://indiadial.in/ | B26: 34 | C26: 55 | D26: Profile Creation | E26: https://indiadial.in/my-profile.html
A27: https://www.articlealley.com/ | B27: 53 | C27: 52 | D27: Profile Creation | E27: https://www.articlealley.com/profile/ritzgroup
A28: https://indiafinder.in/ | B28: 14 | C28: 26 | D28: Profile Creation | E28: https://indiafinder.in/users/profile
A29: 30/12/2025
A30: https://www.beatstars.com/ | B30: 80 | C30: 60 | D30: Profile Creation | E30: https://www.beatstars.com/ritzgroupco123
A31: futurelab.my | B31: 35 | C31: 40 | D31: Profile Creation | E31: https://futurelab.my/mentee_profile/ritz-group
A32: https://tm-town.com/ | B32: 40 | C32: 46 | D32: Profile Creation | E32: https://tm-town.com///translators/ritzgroup
A33: https://www.jobcase.com | B33: 54 | C33: 52 | D33: Profile Creation | E33: https://www.jobcase.com/profile
A34: https://www.longisland.com | B34: 81 | C34: 59 | D34: Profile Creation | E34: https://www.longisland.com/accounts/overview/
A35: https://dash.e.jimdo.com/ | B35: 43 | C35: 54 | D35: Profile Creation | E35: https://dash.e.jimdo.com/profile
A36: https://www.mikroe.com/ | B36: 59 | C36: 51 | D36: Profile Creation | E36: https://www.mikroe.com/my-account
A37: https://www.stocksy.com/ | B37: 69 | C37: 56 | D37: Profile Creation | E37: https://www.stocksy.com/user/edit-profile
A38: https://www.alamy.com | B38: 91 | C38: 66 | D38: Profile Creation | E38: https://www.alamy.com/myalamycustomer.aspx
A39: https://www.ning.com/ | B39: 59 | C39: 51 | D39: Profile Creation | E39: https://www.ning.com/account
A40: https://businessdirectoryphil.com/ | B40: 34 | C40: 57 | D40: Profile Creation | E40: https://businessdirectoryphil.com/wp-admin/profile.php
...

Sheet Social Bookmarks
A1: Referring URl | B1: DA | C1: PA | D1: Type of Submission | E1: Submitted URl | F1: Status
A2: https://bookmarkrange.com/ | B2: 11 | C2: 42 | D2: SBMS | E2: https://bookmarkrange.com/story22617237/how-to-choose-the-right-investment-company-for-long-term-wealth-growth
A3: https://bookmarkbirth.com/ | B3: 15 | C3: 40 | D3: SBMS | E3: https://bookmarkbirth.com/story21340511/how-to-choose-the-right-investment-company-for-long-term-wealth-growth | G3: Gmail | H3: Password
A4: https://www.bookmarkfeeds.com | B4: 55 | C4: 64 | D4: SBMS | E4: https://www.bookmarkfeeds.com/how-to-choose-the-right-investment-company-for-long-term-wealth-growth/ | G4: ritzgroupco123@gmail.com | H4: Ritzgroup@1122
A5: https://www.socialbookmarknow.info/ | B5: 18 | C5: 41 | D5: SBMS | E5: https://www.socialbookmarknow.info/how-to-choose-the-right-investment-company-for-long-term-wealth-growth/
A6: https://www.publicbuysell.com/ | B6: 42 | C6: 55 | D6: SBMS | E6: https://www.publicbuysell.com/how-to-choose-the-right-investment-company-for-long-term-wealth-growth/
A7: 24/12/2025
A8: https://www.submitcorp.com/ | B8: 28 | C8: 50 | D8: SBMS | E8: https://www.submitcorp.com/how-an-investors-club-can-boost-your-investment-knowledge-profits/
A9: https://www.peoplebookmarks.com/ | B9: 12 | C9: 41 | D9: SBMS | E9: https://www.peoplebookmarks.com/how-an-investors-club-can-boost-your-investment-knowledge-profits/
A10: https://altbookmark.com/ | B10: 86 | C10: 52 | D10: SBMS | E10: https://altbookmark.com/story22701218/how-an-investors-club-can-boost-your-investment-knowledge-profits
A11: https://hindibookmark.com/ | B11: 97 | C11: 87 | D11: SBMS | E11: https://hindibookmark.com/story22786728/how-an-investors-club-can-boost-your-investment-knowledge-profits
A12: https://www.legacydirectory.com/ | B12: 34 | C12: 38 | D12: SBMS | E12: https://www.legacydirectory.com/how-an-investors-club-can-boost-your-investment-knowledge-profits/
A13: 29/12/2025
A14: https://www.bookmarkbuzz.com | B14: 15 | C14: 41 | E14: https://www.bookmarkbuzz.com/top-fund-management-services-in-india-features-benefits-how-to-choose-the-right-one/
A15: https://www.directorynode.com | B15: 22 | C15: 41 | E15: https://directorynode.com/top-fund-management-services-in-india-features-benefits-how-to-choose-the-right-one/
A16: https://www.bookmarkinbox.info | B16: 14 | C16: 42 | E16: https://www.bookmarkinbox.info/top-fund-management-services-in-india-features-benefits-how-to-choose-the-right-one/
A17: https://www.indusdirectory.com | B17: 17 | C17: 38 | E17: https://www.indusdirectory.com/top-fund-management-services-in-india-features-benefits-how-to-choose-the-right-one/
A18: directorysection.com | B18: 16 | C18: 42 | E18: https://www.socialbookmarkiseasy.info/micro-macro-investments-in-india-a-complete-guide-for-smart-wealth-building-in-2025/
A19: 30/12/2025
A20: https://bouchesocial.com | B20: 75 | C20: 55 | E20: https://bouchesocial.com/story23065424/ritz-group-greentech-fintech-healthtech-investments-building-the-future-of-smart-capital
A21: https://socialmarkz.com | B21: 45 | C21: 34 | E21: https://socialmarkz.com/story11425277/how-to-choose-the-right-investment-company-for-long-term-wealth-growth
A22: https://bookmarketmaven.com | B22: 66 | C22: 75 | E22: https://bookmarketmaven.com/story21659913/how-an-investors-club-can-boost-your-investment-knowledge-profits
A23: https://socialmphl.com/ | B23: 55 | C23: 46 | E23: https://socialmphl.com/story23061197/top-fund-management-services-in-india-features-benefits-how-to-choose-the-right-one
A24: https://socialmediainuk.com/ | B24: 26 | C24: 46 | E24: https://socialmediainuk.com/story25218660/ritz-group-greentech-fintech-healthtech-investments-building-the-future-of-smart-capital
A25: https://start.me/ | B25: 19 | C25: 41 | E25: https://start.me/p/YQjDqJ/ritz-group-greentech-fintech-healthtech-inves
A26: https://www.social-bookmarkingsites.com/ | B26: 31 | C26: 40 | E26: https://www.social-bookmarkingsites.com/story/ritz-group-greentech-fintech-healthtech-investments-building-the-future-of-smart-capital-2
A27: https://www.sbookmarking.com/ | B27: 18 | C27: 41 | E27: https://www.sbookmarking.com/profile
A28: 31/12/2025
A29: https://www.submitportal.com/ | B29: 14 | C29: 41 | E29: https://www.submitportal.com/micro-macro-investments-in-india-a-complete-guide-for-smart-wealth-building-in-2025/
A30: https://www.activebookmarks.com | B30: 30 | C30: 50 | E30: https://www.activebookmarks.com/preview-bookmark/
A31: https://www.bsocialbookmarking.info | B31: 23 | C31: 45 | E31: https://www.bsocialbookmarking.info/top-fund-management-services-in-india-features-benefits-how-to-choose-the-right-one/
A32: https://www.votetags.com | B32: 27 | C32: 49 | E32: https://www.votetags.com/how-an-investors-club-can-boost-your-investment-knowledge-profits/
A33: https://www.onlinewebmarks.com | B33: 28 | C33: 50 | E33: https://www.onlinewebmarks.com/how-to-choose-the-right-investment-company-for-long-term-wealth-growth/
A34: https://www.bookmarktheme.com | B34: 22 | C34: 44 | E34: https://www.bookmarktheme.com/best-investment-company-in-india/
A35: 46054
A36: https://bookmark-share.com/ | B36: 28 | C36: 40 | E36: https://bookmark-share.com/story20924506/top-venture-capital-firms-in-india-2025-the-ultimate-guide-for-startup-founders
A37: https://hypebookmarking.com/ | B37: 38 | C37: 43 | E37: https://hypebookmarking.com/story20651953/best-investment-company-in-india
A38: https://www.richbookmarks.com | B38: 74 | C38: 68 | E38: https://www.richbookmarks.com/fund-management-services-in-india/
A39: https://www.bookmarkwiki.com/ | B39: 50 | C39: 50 | E39: https://www.bookmarkwiki.com/ritz-group-%e2%80%93-greentech-fintech-healthtech-investments-building-the-future-of-smart-capital/
A40: https://www.premiumbookmarks.com/ | B40: 35 | C40: 43 | E40: https://www.premiumbookmarks.com/how-to-choose-the-right-investment-company-for-long-term-wealth-growth/
...

Sheet Directorites Submissions
A1: Referring URl | B1: DA | C1: PA | D1: Type of Submission | E1: Submitted URl | F1: Status
A2: https://caida.eu/ | B2: 17 | C2: 45 | D2: Directories | E2: https://caida.eu/submit.php
A3: https://www.fire-directory.com/ | B3: 32 | C3: 51 | D3: Directories | E3: https://www.fire-directory.com/submit.php | G3: Gmail | H3: Password
A4: https://www.craigslist.org/ | B4: 88 | C4: 76 | D4: Directories | E4: https://hyderabad.craigslist.org/fns/d/how-to-choose-the-right-investment/7904178770.html | G4: ritzgroupco123@gmail.com | H4: Ritzgroup@1122
A5: https://linkdirectorylistings.org/ | B5: 73 | C5: 42 | D5: Directories | E5: https://linkdirectorylistings.org/submit-site/
A6: https://www.dizila.com/ | B6: 17 | C6: 45 | D6: Directories | E6: https://www.dizila.com/submit?c=27&LINK_TYPE=1
A7: 24/12/2025
A8: https://www.firstlinkonline.info/ | B8: 65 | C8: 39 | D8: Directories | E8: https://www.firstlinkonline.info/submit.php?c=702&LINK_TYPE=8
A9: https://www.qualityinternetdirectory.com | B9: 20 | C9: 44 | D9: Directories | E9: https://www.qualityinternetdirectory.com/submit.php
A10: https://www.freeprwebdirectory.com | B10: 15 | C10: 50 | D10: Directories | E10: https://www.freeprwebdirectory.com/submit.php
A11: https://www.submissionwebdirectory.com | B11: 28 | C11: 28 | D11: Directories | E11: https://www.submissionwebdirectory.com/submit.php
A12: https://www.prolinkdirectory.com/ | B12: 34 | C12: 67 | D12: Directories | E12: https://www.prolinkdirectory.com/submit.php
A13: 29/12/2025
A14: https://www.247webdirectory.com/ | B14: 24 | C14: 51 | E14: https://www.247webdirectory.com/?aspxerrorpath=/save.aspx
A15: https://www.ecobluedirectory.com/ | B15: 31 | C15: 45 | E15: https://www.ecobluedirectory.com/submit.php
A16: https://www.greenydirectory.com/ | B16: 22 | C16: 44 | E16: https://www.greenydirectory.com/submit.php
A17: https://www.reddit-directory.com/ | B17: 32 | C17: 46 | E17: https://www.reddit-directory.com/submit.php
A18: https://www.jayde.com/ | B18: 41 | C18: 56 | E18: https://www.jayde.com/landing.html
A19: 30/12/2025
A20: https://www.groovy-directory.com/ | B20: 13 | C20: 39 | E20: https://www.groovy-directory.com/submit.php
A21: https://www.craigslistdirectory.net/ | B21: 19 | C21: 41 | E21: https://www.bluesparkledirectory.com/submit.php
A22: https://alive-directory.com/ | B22: 78 | C22: 63 | E22: https://alive-directory.com/submit.php
A23: https://www.submissionwebdirectory.com | B23: 54 | C23: 42 | E23: https://www.submissionwebdirectory.com/submit.php
A24: https://www.cipinet.com/ | B24: 73 | C24: 52 | E24: https://www.cipinet.com/Business/Financial_Services/
A25: https://www.highrankdirectory.com/ | B25: 65 | C25: 85 | E25: https://www.highrankdirectory.com/submit.php?id=671
A26: https://localpages.com/ | B26: 47 | C26: 33 | E26: https://localpages.com/business-listing
A27: 31/12/2025
A28: https://www.qualityinternetdirectory.com | B28: 20 | C28: 44 | E28: https://www.qualityinternetdirectory.com/submit.php
A29: https://www.freeprwebdirectory.com | B29: 15 | C29: 50 | E29: https://www.firstlinkonline.info/submit.php?c=702&LINK_TYPE=8
A30: https://www.submissionwebdirectory.com | B30: 28 | C30: 28 | E30: https://www.freeprwebdirectory.com/submit.php
A31: https://www.bluebook-directory.com/ | B31: 32 | C31: 51 | E31: https://www.bluebook-directory.com/submit.php
A32: https://www.interesting-dir.com/ | B32: 34 | C32: 67 | E32: https://www.interesting-dir.com/submit.php
A33: 46054
A34: https://www.canadawebdir.com/ | B34: 82 | C34: 69 | E34: https://www.canadawebdir.com/submit.php
A35: https://www.canadiandirectory.org/ | B35: 25 | C35: 42 | E35: https://www.canadiandirectory.org/submit.php
A36: https://www.gtawebdirectory.com/ | B36: 58 | C36: 58 | E36: https://www.gtawebdirectory.com/submit.php
A37: https://www.fire-directory.com/ | B37: 48 | C37: 50 | E37: https://www.fire-directory.com/submit.php
A38: https://www.submissionwebdirectory.com/ | B38: 44 | C38: 49 | E38: https://www.submissionwebdirectory.com/submit.php
A39: https://www.fire-directory.com/ | B39: 44 | C39: 49 | E39: https://www.fire-directory.com/submit.php
A40: 46143
...

Sheet Classifieds Submissions
A1: Referring URl | B1: DA | C1: PA | D1: Type of Submission | E1: Submitted URl | F1: Status
A2: https://www.locanto.org | B2: 15 | C2: 23 | D2: Clasifieds | E2: https://www.locanto.org/nanakramguda/ID_8111869115/How-to-Choose-the-Right-Investment-Company-for-Long-Term-Wealth.html | H2: Gmail | I2: Password
A3: https://www.freeclassifiedssites.com/ | B3: 29 | C3: 50 | D3: Clasifieds | E3: https://www.freeclassifiedssites.com/index.php?view=post&cityid=609&lang=en&catid=12&subcatid=82&shortcutregion=& | H3: ritzgroupco123@gmail.com | I3: Ritzgroup@1122
A4: https://hyderabad.indads.in/ | B4: 20 | C4: 34 | D4: Clasifieds | E4: https://hyderabad.indads.in/item/1370065/
A5: https://hyderabad.classifiedsfactor.com/ | B5: 26 | C5: 29 | D5: Clasifieds | E5: https://items.classifiedsfactor.com/post-a-classified-ad-type.php
A6: https://www.advertiseera.com | B6: 22 | C6: 44 | D6: Clasifieds | E6: https://www.advertiseera.com/post-an-ad-step-6.php
A7: 24/12/2025
A8: https://indianapolis.claz.org/ | B8: 23 | C8: 43 | D8: Clasifieds | E8: https://indianapolis.claz.org/classifieds/services/finance/l272bbmn8a6xr-best-investment-company-in-india
A9: https://www.classifiedads.com | B9: 61 | C9: 35 | D9: Clasifieds | E9: https://www.classifiedads.com/financial_services/688z5knvb3dx9
A10: https://chennaiclassic.com/ | B10: 19 | C10: 48 | D10: Clasifieds | E10: https://chennaiclassic.com/listing/best-investment-company-in-india/
A11: https://www.yookalo.com | B11: 75 | C11: 86 | D11: Clasifieds | E11: https://www.yookalo.com/item-success
A12: 29/12/2025
A13: freeadsincanada.com | B13: 23 | C13: 43 | E13: http://andhra-pradesh.freeadsinindia.in/en-i-editResourceOffer-i-id-i-3212786-i-best-investment-company-in-india-ritzgroup.html
A14: https://www.canadianplanet.net | B14: 26 | C14: 50 | E14: https://www.canadianplanet.net/ritzgroup-investment-organization-F1108C1061BD54C
A15: https://www.classifiedsfactor.com/ | B15: 35 | C15: 56 | E15: https://items.classifiedsfactor.com/post-a-classified-ad-type.php
A16: https://www.topfreeclassifieds.com | B16: 14 | C16: 29 | E16: https://www.topfreeclassifieds.com/index.php?view=post&cityid=16&lang=en&catid=12&subcatid=82&shortcutregion=&
A17: https://indiadial.in | B17: 14 | C17: 26 | E17: https://indiadial.in/services/finance-legal/financial-advice/best-investment-company-in-india-291425.html
A18: 30/12/2025
A19: https://www.locanto.org | B19: 15 | C19: 23 | E19: https://www.locanto.org/nanakramguda/ID_8129985068/Ritz-Group-GreenTech-FinTech-HealthTech-Investments-Buildi.html
A20: https://hyderabad.craigslist.org/ | B20: 88 | C20: 67 | E20: https://hyderabad.craigslist.org/fns/d/ritz-group-greentech-fintech-healthtech/7905429805.html
A21: https://hyderabad.indads.in/ | B21: 20 | C21: 34 | E21: https://hyderabad.indads.in/item/1372245/
A22: https://www.freeclassifiedssites.com/ | B22: 29 | C22: 50 | E22: https://www.freeclassifiedssites.com/index.php?view=post&cityid=609&lang=en&catid=12&subcatid=82&shortcutregion=&
A23: https://GlobalClassified.net/ | B23: 33 | C23: 29 | E23: https://GlobalClassified.net/464/posts/3/20/1964125.html
A24: 31/12/2025
A25: https://in.classi4u.com/ | B25: 88 | C25: 76 | E25: https://in.classi4u.com/p/hyderabad-best-investment-company-in-india-pid4370501
A26: https://www.yookalo.com | B26: 75 | C26: 86 | E26: https://www.yookalo.com/item/new?e=team@ritzgroup.co
A27: https://eonlineads.com/ | B27: 21 | C27: 45 | E27: https://eOnlineAds.com/464/posts/3/20/1834908.html
A28: https://unolist.in/ | B28: 34 | C28: 55 | E28: https://unolist.in/desc/744213_Best-Investment-Company-in-India.html
A29: https://www.vivastreet.co.in/ | B29: 55 | C29: 28 | E29: https://www.vivastreet.co.in/user/account/ads
A30: https://www.adpost.com/ | B30: 44 | C30: 84 | E30: https://www.adpost.com/in/business_opportunities/484675/
A31: 46054
A32: https://www.topclassifieds.com/a | B32: 82 | C32: 69 | E32: https://www.topclassifieds.com/ads/16/posts/16-Services/144-Financial/5512955-Best-Investment-Company-in-India.html
A33: https://FreeWebAds.biz/ | B33: 25 | C33: 42 | E33: https://FreeWebAds.biz/464/posts/3/20/1857162.html
A34: https://www.locanto.org/ | B34: 58 | C34: 58 | E34: https://www.locanto.org/nanakramguda/ID_8137941986/Top-Venture-Capital-Firms-in-India-2025.html
A35: https://www.wallclassifieds.com/ | B35: 48 | C35: 50 | E35: https://www.wallclassifieds.com/post-a-free-ad-process-phone.php
A36: https://hyderabad.craigslist.org/ | B36: 44 | C36: 49 | E36: https://hyderabad.craigslist.org/fns/d/top-venture-capital-firms-in-india-2025/7905986089.html
A37: https://Classified4Free.net/ | B37: 35 | C37: 56 | E37: https://Classified4Free.net/464/posts/3/20/1812057.html
A38: 46143
A39: https://unolist.in/ | B39: 88 | C39: 67 | E39: https://unolist.in/desc/744923_Best-Investment-Company-in-India.html
A40: claz.org | B40: 20 | C40: 34 | E40: https://indianapolis.claz.org/classifieds/services/finance/l27cip4yjtfg0-business-investors-in-india-why
...

Sheet Artical Submissions
A1: Referring URl | B1: DA | C1: PA | D1: Type of Submission | E1: Submitted URl | F1: Status
A2: https://articlebiz.com/ | B2: 46 | C2: 53 | E2: https://articlebiz.com/checkArticle/statuses/ritzgroupco123%40gmail.com
A3: articlealley.com | B3: 53 | C3: 52 | E3: https://www.articlealley.com/list/best-investment-company-in-india-82825
A4: https://blog.freeadstime.org | B4: 37 | C4: 48 | E4: https://blogpost.freeadstime.org/post-an-article-steps.php
A5: 31/12/2025
A6: https://article.advertiseera.com/ | B6: 22 | C6: 19 | E6: https://article.advertiseera.com/article-submitted/
A7: 27/1/2026
A8: https://articlebiz.com/ | E8: https://articlebiz.com/checkArticle/statuses/team%40ritzgroup.co
A9: https://article.advertiseera.com/ | E9: https://article.advertiseera.com/article-submitted/
A10: 46328
A11: https://www.webdirectoryhealth.com/ | E11: https://www.webdirectoryhealth.com/submit_article.php
A12: https://articles.abilogic.com/ | E12: https://articles.abilogic.com/myaccount/articles/manage/1/1/
A13: https://articlebiz.com/checkArticle/ | E13: https://articlebiz.com/checkArticle/statuses/ritzgroupco123%40gmail.com
A14: 16/02/2026
A15: https://www.marketinginternetdirectory.com/ | B15: 30 | C15: 47 | E15: https://www.marketinginternetdirectory.com/submit_article.php
A16: https://promotebusinessdirectory.com/ | B16: 25 | C16: 25 | E16: https://promotebusinessdirectory.com/article_payment.php?id=10937239
A17: https://www.highrankdirectory.com/ | B17: 41 | C17: 45 | E17: https://www.highrankdirectory.com/submit_article.php
A18: https://www.siteswebdirectory.com | B18: 48 | C18: 28 | E18: https://www.siteswebdirectory.com/submit_article.php
A19: https://www.freeprwebdirectory.com | B19: 55 | C19: 34 | E19: https://www.freeprwebdirectory.com/submit_article.php
A20: https://www.theseobacklink.com/ | B20: 26 | C20: 28 | E20: https://www.theseobacklink.com/submit-article
A21: 17/02/2026
A22: https://www.freeprwebdirectory.com/ | B22: 55 | C22: 34 | E22: https://www.freeprwebdirectory.com/submit_article.php
A23: https://www.usalistingdirectory.com/ | B23: 31 | C23: 48 | E23: https://www.usalistingdirectory.com/submit_article.php
A24: https://ritzgroup.livepositively.com/ | B24: 61 | C24: 57 | E24: https://ritzgroup.livepositively.com/why-ritz-group-is-investing-in-greentech-fintech-and-healthtech-for-a-better-tomorrow
A25: https://theomnibuzz.com/ | B25: 58 | C25: 52 | E25: https://theomnibuzz.com/best-investment-company-in-india--how-to-choose-the-right-partner-for-your-financial-growtht-titl
A26: 19/02/2026
A27: https://ritzgroup.livepositively.com/ | B27: 61 | C27: 57 | E27: https://ritzgroup.livepositively.com/business-investors-and-investor-clubs-a-complete-guide-to-funding-and-wealth-creation
A28: https://theomnibuzz.com/ | B28: 58 | C28: 52 | E28: https://theomnibuzz.com/business-investors---investor-clubs--a-complete-guide-to-funding-and-wealth-creation
A29: https://www.freeprwebdirectory.com/ | B29: 55 | C29: 34 | E29: https://www.freeprwebdirectory.com/submit_article.php
A30: https://www.usalistingdirectory.com/ | B30: 31 | C30: 48 | E30: https://www.usalistingdirectory.com/submit_article.php
A31: https://articles.h1ad.com/ | E31: https://articles.h1ad.com/article-submitted/
A32: 20/02/2026
A33: https://www.marketinginternetdirectory.com/ | B33: 30 | C33: 47 | E33: https://www.marketinginternetdirectory.com/submit_article.php
A34: https://promotebusinessdirectory.com/ | B34: 25 | C34: 25 | E34: https://promotebusinessdirectory.com/article_payment.php?id=10951186
A35: https://www.highrankdirectory.com/ | B35: 41 | C35: 45 | E35: https://www.highrankdirectory.com/submit_article.php
A36: https://www.highrankdirectory.com/ | B36: 50 | C36: 31 | E36: https://www.highrankdirectory.com/submit_article.php
A37: https://www.siteswebdirectory.com | B37: 48 | C37: 28 | E37: https://www.siteswebdirectory.com/submit_article.php
A38: https://www.theseobacklink.com/ | B38: 26 | C38: 28 | E38: https://www.theseobacklink.com/submit-article
A39: https://fWebDirectory.com/ | B39: 32 | C39: 25 | E39: https://fWebDirectory.com/464/posts/3/20/2002466.html

Sheet Pdf Submissions
A1: Referring URl | B1: DA | C1: PA | D1: Type of Submission | E1: Submitted URl | F1: Status
A2: http://www.pinpdf.com/ | B2: 31 | C2: 37 | E2: https://pinpdf.com/best-investment-company-in-india-466f1065019d54dc0318ac914b162031.html
A3: www.slideshare.net | B3: 94 | C3: 86 | E3: https://www.slideshare.net/slideshow/ritz-group-greentech-fintech-healthtech-investments/284886954 | G3: Gmail | H3: Password
A4: dochub.com | B4: 60 | C4: 58 | E4: https://www.docdroid.com/lEnO9Ck/off-page-pdf | G4: ritzgroupco123@gmail.com | H4: Ritzgroup@1122
A5: issuu.com | B5: 94 | C5: 83 | E5: https://issuu.com/ritzgroup/docs/best_investment_company_in_india
A6: www.smallpdf.com | B6: 72 | C6: 57 | E6: https://smallpdf.com/edit-pdf#r=result&t=c5990256934f1f401f3eb65b4b5d8531&i=annotate
A7: dochub.com | B7: 60 | C7: 58 | E7: https://dochub.com/ritz-group/7vA0q9lw2bQnPZEwPDNOxd/off-page-1-pdf?pg=3
A8: https://www.4shared.com/ | B8: 94 | C8: 74 | E8: https://www.4shared.com/web/preview/pdf/MygdS0wJjq?
A9: https://www.scribd.com | B9: 45 | C9: 66 | E9: https://www.scribd.com/document/974003863/Best-Investment-Company-in-India?secret_password=49Q5Kbw04xBjl3iLCEsn
A10: https://www.pdfhost.net/ | B10: 79 | C10: 62 | E10: https://www.pdfhost.net/index.php?Action=UploadFile
A11: 31/12/2025
A12: www.degoo.com | B12: 55 | C12: 44 | E12: https://app.degoo.com/files/0?ID=20808314304
A13: www.dochub.com | B13: 60 | C13: 53 | E13: https://dochub.com/ritz-group/JWop0ZAKk8YLdllVrYa9GP/off-page-pdf
A14: https://www.scribd.com | B14: 45 | C14: 66 | E14: https://www.scribd.com/document/974347597/Fund-Management-services-in-India?secret_password=IfX4HthRAlqpFwiWuazn
A15: https://archive.org | B15: 94 | C15: 84 | E15: https://archive.org/details/httpsritzgroup.co
A16: 46143
A17: https://workupload.com/ | B17: 73 | C17: 57 | E17: https://workupload.com/file/LhKhcE73NbB
A18: https://limewire.com/ | B18: 15 | C18: 37 | E18: https://limewire.com/
A19: https://dochub.com/ | B19: 24 | C19: 49 | E19: https://dochub.com/ritz-group/JWop0ZAKk8Y0Je1VrYa9GP/off-page-2-pdf
A20: https://pinpdf.com | B20: 24 | C20: 49 | E20: https://pinpdf.com/top-venture-capital-firms-in-india-2025-3cb9450cfd8c695cb139c8db6d8b1e6c.html
A21: www.tiiny.hostpdf-upload | B21: 25 | C21: 30 | E21: https://black-kelley-30.tiiny.site/
A22: https://files.fm/ | B22: 27 | C22: 38 | E22: https://files.fm/u/mndntxkfzz#/view/q96pg2btkw
A23: https://smallpdf.com/ | B23: 45 | C23: 65 | E23: https://smallpdf.com/pdf-ocr#r=result&t=e935dea3a00101412023f0164fb8cab5&i=ocr
A24: 46204
A25: https://www.4shared.com/ | B25: 94 | C25: 74 | E25: https://www.4shared.com/web/preview/pdf/SA2JaRaiku?
A26: 46266
A27: https://workupload.com/file/nU4Lkj9L24Q | B27: 44 | C27: 67 | E27: https://workupload.com/file/nU4Lkj9L24Q
A28: https://limewire.com/ | B28: 58 | C28: 86 | E28: https://limewire.com/?referrer=cwnprhcil4
A29: https://issuu.com/home/ | B29: 38 | C29: 54 | E29: https://issuu.com/home/docs/eud6y3h9cku/share?post_publish=true
A30: 46357
A31: https://www.4shared.com/ | B31: 43 | C31: 66 | E31: https://www.4shared.com/account/home.jsp#dir=jZuwJ9pJ
A32: https://smallpdf.com/ | B32: 32 | C32: 47 | E32: https://smallpdf.com/pdf-to-jpg#r=result&t=28c11b2a593da939c77b57ee7cba833f&i=convert-to-image
A33: 28/1/2026
A34: http://www.pinpdf.com/ | B34: 31 | C34: 37 | E34: https://pinpdf.com/investment-strategies-for-smart-wealth-creation-a-complete-g-3c728023e7922d594dd29f89e421db
A35: www.slideshare.net | B35: 94 | C35: 86 | E35: https://www.slideshare.net/slideshow/investment-strategies-for-smart-wealth-creation-a-complete-guide-for-modern-investors/285613892#1
A36: dochub.com | B36: 60 | C36: 58 | E36: https://dochub.com/ritz-group/5lae27DR5qaZMNrRmqjZv1/off-page-pdf
A37: issuu.com | B37: 94 | C37: 83 | E37: https://issuu.com/ritzgroup/docs/off_-_page_
A38: www.smallpdf.com | B38: 72 | C38: 57 | E38: https://smallpdf.com/edit-pdf#r=result&t=6a13bdd8d12964a22af692da510511b2&i=annotate
A39: https://www.4shared.com/ | B39: 94 | C39: 74 | E39: https://www.4shared.com/web/preview/pdf/qV5PN6rbjq?
A40: https://www.scribd.com | B40: 45 | C40: 66 | E40: https://www.scribd.com/document/988715097/Investment-Strategies-for-Smart-Wealth-Creation-A-Complete-Guide-for-Modern-Investors?secret_password=HGoXcra7vHIMEqmaPFPm
...

Sheet Image Submissions
A1: Referring URl | B1: DA | C1: PA | D1: Type of Submission | E1: Submitted URl | F1: Status
A2: 46143
A3: https://www.photobucket.com/ | B3: 31 | C3: 37 | D3: Image | E3: https://www.photobucket.com/bucket/22e2f62a-5f5e-4ca3-a283-ed5745866671/media/ce7437a5-d684-4d02-a58e-20b99dae4da6 | G3: Gmail | H3: Password
A4: https://archive.org/ | B4: 94 | C4: 86 | D4: Image | E4: https://archive.org/details/entrepreneurs_202601 | G4: ritzgroupco123@gmail.com | H4: Ritzgroup@1122
A5: https://www.4shared.com/ | B5: 60 | C5: 58 | D5: Image | E5: https://www.4shared.com/account/home.jsp#dir=jZuwJ9pJ
A6: https://www.mediafire.com/ | B6: 94 | C6: 83 | D6: Image | E6: https://www.mediafire.com/file/hauxr78q4gphows/entrepreneurs.jpg/file
A7: https://www.dropbox.com/ | B7: 72 | C7: 57 | D7: Image | E7: https://www.dropbox.com/home?preview=entrepreneurs.jpg
A8: https://postimg.c | B8: 60 | C8: 58 | D8: Image | E8: https://postimg.cc/fSxXZtDJ
A9: https://myphoto.eu/ | B9: 32 | C9: 46 | D9: Image | E9: https://myphoto.eu/ritzgroupco123/photo/841218/investment.jpg
A10: https://app.parler.com/ | B10: 45 | C10: 62 | D10: Image | E10: https://app.parler.com/post/01ke73p9k1256tzbrcnxq1jwh9
A11: 46174
A12: https://www.imagevenue.com/ | B12: 24 | C12: 66 | D12: Image | E12: https://www.imagevenue.com/ME1C7N2W
A13: https://myphoto.eu/ | B13: 55 | C13: 87 | D13: Image | E13: https://myphoto.eu/ritzgroupco123/photo/841372/entrepreneurs.jpg
A14: https://ibb.co/album/ | B14: 77 | C14: 57 | D14: Image | E14: https://ibb.co/album/6rDBCP
A15: 46235
A16: https://myphoto.eu/ | B16: 55 | C16: 87 | D16: Image | E16: https://myphoto.eu/ritzgroupco123/photo/841634/ritz%20posts%20(2)%202.jpg
A18: 19/1/2026
A19: https://www.photobucket.com/ | B19: 31 | C19: 37 | D19: Image | E19: https://www.photobucket.com/bucket/22e2f62a-5f5e-4ca3-a283-ed5745866671/media/852252be-7417-49d7-aa56-c1000dc1c60d
A20: https://archive.org/ | B20: 94 | C20: 86 | D20: Image | E20: https://archive.org/details/untitled-design-6-1_202601
A21: https://www.4shared.com/ | B21: 60 | C21: 58 | D21: Image | E21: https://www.4shared.com/account/home.jsp#dir=jZuwJ9pJ
A22: https://www.mediafire.com/ | B22: 94 | C22: 83 | D22: Image | E22: https://www.mediafire.com/view/i8v3rusp62h05k6/550414511_122119365926963702_5189767811357890255_n.jpg/file
A23: https://www.dropbox.com/ | B23: 72 | C23: 57 | D23: Image | E23: https://www.dropbox.com/home?preview=Untitled+design+%286%29+%281%29.jpg
A24: https://app.parler.com/ | B24: 45 | C24: 62 | D24: Image | E24: https://app.parler.com/post/01kfayg5s78ha6t8jgkpvdxn69
A25: 22/1/2025
A26: https://www.photobucket.com/ | B26: 31 | C26: 37 | D26: Image | E26: https://www.photobucket.com/bucket/22e2f62a-5f5e-4ca3-a283-ed5745866671/media/f048f545-0422-4a03-9f5b-2bd137a3c649
A27: https://archive.org/ | B27: 94 | C27: 86 | D27: Image | E27: https://archive.org/details/ritz-community-post.jpg
A28: https://www.4shared.com/ | B28: 60 | C28: 58 | D28: Image | E28: https://www.4shared.com/account/home.jsp#dir=jZuwJ9pJ
A29: https://www.mediafire.com/ | B29: 94 | C29: 83 | D29: Image | E29: https://www.mediafire.com/view/2qy2fagd3ckie1l/Ritz_community_post.jpg.jpeg/file
A30: https://www.dropbox.com/ | B30: 72 | C30: 57 | D30: Image | E30: https://www.dropbox.com/home?preview=Ritz_community_post.jpg
A31: https://app.parler.com/ | B31: 45 | C31: 62 | D31: Image | E31: https://app.parler.com/post/01kfjpykatak5hvmqmpzmm9pfp
A32: https://myphoto.eu/ | B32: 55 | C32: 87 | D32: Image | E32: https://myphoto.eu/ritzgroupco123/photo/842796/Ritz_community_post.jpg.jpeg
A33: 28/1/2025
A34: https://www.photobucket.com/ | B34: 31 | C34: 37 | D34: Image | E34: https://www.photobucket.com/bucket/22e2f62a-5f5e-4ca3-a283-ed5745866671/media/c38d1cff-be1b-4b1b-8208-4ee85c958641
A35: https://archive.org/ | B35: 94 | C35: 86 | D35: Image | E35: https://archive.org/details/ritz-post-3.jpg
A36: https://www.4shared.com/ | B36: 60 | C36: 58 | D36: Image | E36: https://www.4shared.com/account/home.jsp#dir=jZuwJ9pJ
A37: https://www.mediafire.com/ | B37: 94 | C37: 83 | D37: Image | E37: https://www.mediafire.com/view/bglfutp1ue1ykz6/Ritz_post_%25283%2529.jpg.jpeg/file
A38: https://www.dropbox.com/ | B38: 72 | C38: 57 | D38: Image | E38: https://www.dropbox.com/home?preview=Ritz+post+%283%29.jpg.jpeg
A39: https://app.parler.com/ | B39: 45 | C39: 62 | D39: Image | E39: https://app.parler.com/ritzgroupco
